Workbook

Sheet Flights
A1: Date | B1: Week Number | C1: Week Day | D1: Flight | E1: Airline | F1: Origin | G1: Destination | H1: Destination City | I1: Destination State | J1: Scheduled Departure | K1: Scheduled Departure Hour | L1: Departure | M1: Departure Delay(min) | N1: Length (hr) | O1: Length (min) | P1: Distance | Q1: Avergae Speed | R1: Scheduled Arrival | S1: Meal | T1: Open Bar | U1: Arrival | V1: Arrival Delay | W1: Status | X1: Delay Type | Y1: Cancelled | Z1: Cancellation Reason | AA1: Compensation
A2: 42005 | B2: =WEEKNUM(Flights[[#This Row],[Date]], 1) -> 1 | C2: =WEEKDAY(Flights[[#This Row],[Date]],1) -> 5 | D2: AA258 | E2: American Airlines | F2: LAX | G2: MIA | H2: =_xlfn.XLOOKUP(Flights[[#This Row],[Destination]], Airports!$A$2:$A$78, Airports!$D$2:$D$78) -> Miami | I2: {=_xlfn.XLOOKUP(Flights[[#This Row],[Destination]],_xlfn._TRO_TRAILING( Airports!A:A),_xlfn._TRO_TRAILING( Airports!E:E), "Not found")} -> FL | J2: 0.013888889 | K2: =HOUR(Flights[[#This Row],[Scheduled Departure]]) -> 0 | L2: 0.010416667 | M2: =(L2-J2)*24*60 -> -5 | N2: =Flights[[#This Row],[Length (min)]]/60 -> 4.6833333 | O2: 281 | P2: 2342 | Q2: =IFERROR(Flights[[#This Row],[Distance]]/Flights[[#This Row],[Length (hr)]], "") -> 500.07117 | R2: 0.33680556 | S2: =IF(Flights[[#This Row],[Length (hr)]]<2, "No meal", IF(Flights[[#This Row],[Length (hr)]]<3.5, "Light meal", "Full meal")) -> Full meal | T2: =IF(AND(Flights[[#This Row],[Airline]]="US Airways", Flights[[#This Row],[Meal]]="Full Meal"), "Yes", "No") -> No | U2: 0.33055556 | V2: -9 | W2: =IF(Flights[[#This Row],[Arrival Delay]] = "", "Cancelled", IF(Flights[[#This Row],[Arrival Delay]]>15, "Delayed", "On time")) -> On time | X2: =IF(Flights[[#This Row],[Status]]<>"Delayed","", IF(Flights[[#This Row],[Arrival Delay]]>120, "Severe", IF(Flights[[#This Row],[Arrival Delay]]>60, "Major", "Moderate"))) | Y2: FALSE | AA2: =IF(OR(AND(Flights[[#This Row],[Status]]="Cancelled", Flights[[#This Row],[Cancellation Reason]]="Airline/Carrier"), Flights[[#This Row],[Delay Type]]="Severe"), "Yes", "No") -> No
A3: 42005 | B3: =WEEKNUM(Flights[[#This Row],[Date]], 1) -> 1 | C3: =WEEKDAY(Flights[[#This Row],[Date]],1) -> 5 | D3: WN2077 | E3: Southwest | F3: LAX | G3: ABQ | H3: =_xlfn.XLOOKUP(Flights[[#This Row],[Destination]], Airports!$A$2:$A$78, Airports!$D$2:$D$78) -> Albuquerque | I3: {=_xlfn.XLOOKUP(Flights[[#This Row],[Destination]],_xlfn._TRO_TRAILING( Airports!A:A),_xlfn._TRO_TRAILING( Airports!E:E), "Not found")} -> NM | J3: 0.40972222 | K3: =HOUR(Flights[[#This Row],[Scheduled Departure]]) -> 9 | L3: 0.40486111 | M3: =(L3-J3)*24*60 -> -7 | N3: =Flights[[#This Row],[Length (min)]]/60 -> 1.8166667 | O3: 109 | P3: 677 | Q3: =IFERROR(Flights[[#This Row],[Distance]]/Flights[[#This Row],[Length (hr)]], "") -> 372.66055 | R3: 0.52430556 | S3: =IF(Flights[[#This Row],[Length (hr)]]<2, "No meal", IF(Flights[[#This Row],[Length (hr)]]<3.5, "Light meal", "Full meal")) -> No meal | T3: =IF(AND(Flights[[#This Row],[Airline]]="US Airways", Flights[[#This Row],[Meal]]="Full Meal"), "Yes", "No") -> No | U3: 0.52222222 | V3: -3 | W3: =IF(Flights[[#This Row],[Arrival Delay]] = "", "Cancelled", IF(Flights[[#This Row],[Arrival Delay]]>15, "Delayed", "On time")) -> On time | X3: =IF(Flights[[#This Row],[Status]]<>"Delayed","", IF(Flights[[#This Row],[Arrival Delay]]>120, "Severe", IF(Flights[[#This Row],[Arrival Delay]]>60, "Major", "Moderate"))) | Y3: FALSE | AA3: =IF(OR(AND(Flights[[#This Row],[Status]]="Cancelled", Flights[[#This Row],[Cancellation Reason]]="Airline/Carrier"), Flights[[#This Row],[Delay Type]]="Severe"), "Yes", "No") -> No
A4: 42005 | B4: =WEEKNUM(Flights[[#This Row],[Date]], 1) -> 1 | C4: =WEEKDAY(Flights[[#This Row],[Date]],1) -> 5 | D4: US726 | E4: US Airways | F4: LAX | G4: PIT | H4: =_xlfn.XLOOKUP(Flights[[#This Row],[Destination]], Airports!$A$2:$A$78, Airports!$D$2:$D$78) -> Pittsburgh | I4: {=_xlfn.XLOOKUP(Flights[[#This Row],[Destination]],_xlfn._TRO_TRAILING( Airports!A:A),_xlfn._TRO_TRAILING( Airports!E:E), "Not found")} -> PA | J4: 0.47916667 | K4: =HOUR(Flights[[#This Row],[Scheduled Departure]]) -> 11 | L4: 0.48680556 | M4: =(L4-J4)*24*60 -> 11 | N4: =Flights[[#This Row],[Length (min)]]/60 -> 4.7 | O4: 282 | P4: 2136 | Q4: =IFERROR(Flights[[#This Row],[Distance]]/Flights[[#This Row],[Length (hr)]], "") -> 454.46809 | R4: 0.79097222 | S4: =IF(Flights[[#This Row],[Length (hr)]]<2, "No meal", IF(Flights[[#This Row],[Length (hr)]]<3.5, "Light meal", "Full meal")) -> Full meal | T4: =IF(AND(Flights[[#This Row],[Airline]]="US Airways", Flights[[#This Row],[Meal]]="Full Meal"), "Yes", "No") -> Yes | U4: 0.80763889 | V4: 24 | W4: =IF(Flights[[#This Row],[Arrival Delay]] = "", "Cancelled", IF(Flights[[#This Row],[Arrival Delay]]>15, "Delayed", "On time")) -> Delayed | X4: =IF(Flights[[#This Row],[Status]]<>"Delayed","", IF(Flights[[#This Row],[Arrival Delay]]>120, "Severe", IF(Flights[[#This Row],[Arrival Delay]]>60, "Major", "Moderate"))) -> Moderate | Y4: FALSE | AA4: =IF(OR(AND(Flights[[#This Row],[Status]]="Cancelled", Flights[[#This Row],[Cancellation Reason]]="Airline/Carrier"), Flights[[#This Row],[Delay Type]]="Severe"), "Yes", "No") -> No
A5: 42005 | B5: =WEEKNUM(Flights[[#This Row],[Date]], 1) -> 1 | C5: =WEEKDAY(Flights[[#This Row],[Date]],1) -> 5 | D5: AA2419 | E5: American Airlines | F5: LAX | G5: DFW | H5: =_xlfn.XLOOKUP(Flights[[#This Row],[Destination]], Airports!$A$2:$A$78, Airports!$D$2:$D$78) -> Dallas | I5: {=_xlfn.XLOOKUP(Flights[[#This Row],[Destination]],_xlfn._TRO_TRAILING( Airports!A:A),_xlfn._TRO_TRAILING( Airports!E:E), "Not found")} -> TX | J5: 0.48958333 | K5: =HOUR(Flights[[#This Row],[Scheduled Departure]]) -> 11 | L5: 0.50972222 | M5: =(L5-J5)*24*60 -> 29 | N5: =Flights[[#This Row],[Length (min)]]/60 -> 3.2333333 | O5: 194 | P5: 1235 | Q5: =IFERROR(Flights[[#This Row],[Distance]]/Flights[[#This Row],[Length (hr)]], "") -> 381.95876 | R5: 0.70138889 | S5: =IF(Flights[[#This Row],[Length (hr)]]<2, "No meal", IF(Flights[[#This Row],[Length (hr)]]<3.5, "Light meal", "Full meal")) -> Light meal | T5: =IF(AND(Flights[[#This Row],[Airline]]="US Airways", Flights[[#This Row],[Meal]]="Full Meal"), "Yes", "No") -> No | U5: 0.72777778 | V5: 38 | W5: =IF(Flights[[#This Row],[Arrival Delay]] = "", "Cancelled", IF(Flights[[#This Row],[Arrival Delay]]>15, "Delayed", "On time")) -> Delayed | X5: =IF(Flights[[#This Row],[Status]]<>"Delayed","", IF(Flights[[#This Row],[Arrival Delay]]>120, "Severe", IF(Flights[[#This Row],[Arrival Delay]]>60, "Major", "Moderate"))) -> Moderate | Y5: FALSE | AA5: =IF(OR(AND(Flights[[#This Row],[Status]]="Cancelled", Flights[[#This Row],[Cancellation Reason]]="Airline/Carrier"), Flights[[#This Row],[Delay Type]]="Severe"), "Yes", "No") -> No
A6: 42005 | B6: =WEEKNUM(Flights[[#This Row],[Date]], 1) -> 1 | C6: =WEEKDAY(Flights[[#This Row],[Date]],1) -> 5 | D6: OO4535 | E6: Skywest | F6: LAX | G6: LAS | H6: =_xlfn.XLOOKUP(Flights[[#This Row],[Destination]], Airports!$A$2:$A$78, Airports!$D$2:$D$78) -> Las Vegas | I6: {=_xlfn.XLOOKUP(Flights[[#This Row],[Destination]],_xlfn._TRO_TRAILING( Airports!A:A),_xlfn._TRO_TRAILING( Airports!E:E), "Not found")} -> NV | J6: 0.52777778 | K6: =HOUR(Flights[[#This Row],[Scheduled Departure]]) -> 12 | L6: 0.52569444 | M6: =(L6-J6)*24*60 -> -3 | N6: =Flights[[#This Row],[Length (min)]]/60 -> 1.1833333 | O6: 71 | P6: 236 | Q6: =IFERROR(Flights[[#This Row],[Distance]]/Flights[[#This Row],[Length (hr)]], "") -> 199.43662 | R6: 0.57916667 | S6: =IF(Flights[[#This Row],[Length (hr)]]<2, "No meal", IF(Flights[[#This Row],[Length (hr)]]<3.5, "Light meal", "Full meal")) -> No meal | T6: =IF(AND(Flights[[#This Row],[Airline]]="US Airways", Flights[[#This Row],[Meal]]="Full Meal"), "Yes", "No") -> No | U6: 0.575 | V6: -6 | W6: =IF(Flights[[#This Row],[Arrival Delay]] = "", "Cancelled", IF(Flights[[#This Row],[Arrival Delay]]>15, "Delayed", "On time")) -> On time | X6: =IF(Flights[[#This Row],[Status]]<>"Delayed","", IF(Flights[[#This Row],[Arrival Delay]]>120, "Severe", IF(Flights[[#This Row],[Arrival Delay]]>60, "Major", "Moderate"))) | Y6: FALSE | AA6: =IF(OR(AND(Flights[[#This Row],[Status]]="Cancelled", Flights[[#This Row],[Cancellation Reason]]="Airline/Carrier"), Flights[[#This Row],[Delay Type]]="Severe"), "Yes", "No") -> No
A7: 42005 | B7: =WEEKNUM(Flights[[#This Row],[Date]], 1) -> 1 | C7: =WEEKDAY(Flights[[#This Row],[Date]],1) -> 5 | D7: VX412 | E7: Virgin America | F7: LAX | G7: JFK | H7: =_xlfn.XLOOKUP(Flights[[#This Row],[Destination]], Airports!$A$2:$A$78, Airports!$D$2:$D$78) -> New York | I7: {=_xlfn.XLOOKUP(Flights[[#This Row],[Destination]],_xlfn._TRO_TRAILING( Airports!A:A),_xlfn._TRO_TRAILING( Airports!E:E), "Not found")} -> NY | J7: 0.56944444 | K7: =HOUR(Flights[[#This Row],[Scheduled Departure]]) -> 13 | L7: 0.56597222 | M7: =(L7-J7)*24*60 -> -5 | N7: =Flights[[#This Row],[Length (min)]]/60 -> 4.9666667 | O7: 298 | P7: 2475 | Q7: =IFERROR(Flights[[#This Row],[Distance]]/Flights[[#This Row],[Length (hr)]], "") -> 498.32215 | R7: 0.91666667 | S7: =IF(Flights[[#This Row],[Length (hr)]]<2, "No meal", IF(Flights[[#This Row],[Length (hr)]]<3.5, "Light meal", "Full meal")) -> Full meal | T7: =IF(AND(Flights[[#This Row],[Airline]]="US Airways", Flights[[#This Row],[Meal]]="Full Meal"), "Yes", "No") -> No | U7: 0.89791667 | V7: -27 | W7: =IF(Flights[[#This Row],[Arrival Delay]] = "", "Cancelled", IF(Flights[[#This Row],[Arrival Delay]]>15, "Delayed", "On time")) -> On time | X7: =IF(Flights[[#This Row],[Status]]<>"Delayed","", IF(Flights[[#This Row],[Arrival Delay]]>120, "Severe", IF(Flights[[#This Row],[Arrival Delay]]>60, "Major", "Moderate"))) | Y7: FALSE | AA7: =IF(OR(AND(Flights[[#This Row],[Status]]="Cancelled", Flights[[#This Row],[Cancellation Reason]]="Airline/Carrier"), Flights[[#This Row],[Delay Type]]="Severe"), "Yes", "No") -> No
A8: 42005 | B8: =WEEKNUM(Flights[[#This Row],[Date]], 1) -> 1 | C8: =WEEKDAY(Flights[[#This Row],[Date]],1) -> 5 | D8: AA28 | E8: American Airlines | F8: LAX | G8: MIA | H8: =_xlfn.XLOOKUP(Flights[[#This Row],[Destination]], Airports!$A$2:$A$78, Airports!$D$2:$D$78) -> Miami | I8: {=_xlfn.XLOOKUP(Flights[[#This Row],[Destination]],_xlfn._TRO_TRAILING( Airports!A:A),_xlfn._TRO_TRAILING( Airports!E:E), "Not found")} -> FL | J8: 0.625 | K8: =HOUR(Flights[[#This Row],[Scheduled Departure]]) -> 15 | L8: 0.62222222 | M8: =(L8-J8)*24*60 -> -4 | N8: =Flights[[#This Row],[Length (min)]]/60 -> 5.0833333 | O8: 305 | P8: 2342 | Q8: =IFERROR(Flights[[#This Row],[Distance]]/Flights[[#This Row],[Length (hr)]], "") -> 460.72131 | R8: 0.95138889 | S8: =IF(Flights[[#This Row],[Length (hr)]]<2, "No meal", IF(Flights[[#This Row],[Length (hr)]]<3.5, "Light meal", "Full meal")) -> Full meal | T8: =IF(AND(Flights[[#This Row],[Airline]]="US Airways", Flights[[#This Row],[Meal]]="Full Meal"), "Yes", "No") -> No | U8: 0.95902778 | V8: 11 | W8: =IF(Flights[[#This Row],[Arrival Delay]] = "", "Cancelled", IF(Flights[[#This Row],[Arrival Delay]]>15, "Delayed", "On time")) -> On time | X8: =IF(Flights[[#This Row],[Status]]<>"Delayed","", IF(Flights[[#This Row],[Arrival Delay]]>120, "Severe", IF(Flights[[#This Row],[Arrival Delay]]>60, "Major", "Moderate"))) | Y8: FALSE | AA8: =IF(OR(AND(Flights[[#This Row],[Status]]="Cancelled", Flights[[#This Row],[Cancellation Reason]]="Airline/Carrier"), Flights[[#This Row],[Delay Type]]="Severe"), "Yes", "No") -> No
A9: 42005 | B9: =WEEKNUM(Flights[[#This Row],[Date]], 1) -> 1 | C9: =WEEKDAY(Flights[[#This Row],[Date]],1) -> 5 | D9: OO6528 | E9: Skywest | F9: LAX | G9: PHX | H9: =_xlfn.XLOOKUP(Flights[[#This Row],[Destination]], Airports!$A$2:$A$78, Airports!$D$2:$D$78) -> Phoenix | I9: {=_xlfn.XLOOKUP(Flights[[#This Row],[Destination]],_xlfn._TRO_TRAILING( Airports!A:A),_xlfn._TRO_TRAILING( Airports!E:E), "Not found")} -> AZ | J9: 0.69513889 | K9: =HOUR(Flights[[#This Row],[Scheduled Departure]]) -> 16 | L9: 0.69027778 | M9: =(L9-J9)*24*60 -> -7 | N9: =Flights[[#This Row],[Length (min)]]/60 -> 1.3333333 | O9: 80 | P9: 370 | Q9: =IFERROR(Flights[[#This Row],[Distance]]/Flights[[#This Row],[Length (hr)]], "") -> 277.5 | R9: 0.79513889 | S9: =IF(Flights[[#This Row],[Length (hr)]]<2, "No meal", IF(Flights[[#This Row],[Length (hr)]]<3.5, "Light meal", "Full meal")) -> No meal | T9: =IF(AND(Flights[[#This Row],[Airline]]="US Airways", Flights[[#This Row],[Meal]]="Full Meal"), "Yes", "No") -> No | U9: 0.7875 | V9: -11 | W9: =IF(Flights[[#This Row],[Arrival Delay]] = "", "Cancelled", IF(Flights[[#This Row],[Arrival Delay]]>15, "Delayed", "On time")) -> On time | X9: =IF(Flights[[#This Row],[Status]]<>"Delayed","", IF(Flights[[#This Row],[Arrival Delay]]>120, "Severe", IF(Flights[[#This Row],[Arrival Delay]]>60, "Major", "Moderate"))) | Y9: FALSE | AA9: =IF(OR(AND(Flights[[#This Row],[Status]]="Cancelled", Flights[[#This Row],[Cancellation Reason]]="Airline/Carrier"), Flights[[#This Row],[Delay Type]]="Severe"), "Yes", "No") -> No
A10: 42005 | B10: =WEEKNUM(Flights[[#This Row],[Date]], 1) -> 1 | C10: =WEEKDAY(Flights[[#This Row],[Date]],1) -> 5 | D10: AS461 | E10: Alaska Airlines | F10: LAX | G10: SEA | H10: =_xlfn.XLOOKUP(Flights[[#This Row],[Destination]], Airports!$A$2:$A$78, Airports!$D$2:$D$78) -> Seattle | I10: {=_xlfn.XLOOKUP(Flights[[#This Row],[Destination]],_xlfn._TRO_TRAILING( Airports!A:A),_xlfn._TRO_TRAILING( Airports!E:E), "Not found")} -> WA | J10: 0.73611111 | K10: =HOUR(Flights[[#This Row],[Scheduled Departure]]) -> 17 | L10: 0.73125 | M10: =(L10-J10)*24*60 -> -7 | N10: =Flights[[#This Row],[Length (min)]]/60 -> 2.7 | O10: 162 | P10: 954 | Q10: =IFERROR(Flights[[#This Row],[Distance]]/Flights[[#This Row],[Length (hr)]], "") -> 353.33333 | R10: 0.84791667 | S10: =IF(Flights[[#This Row],[Length (hr)]]<2, "No meal", IF(Flights[[#This Row],[Length (hr)]]<3.5, "Light meal", "Full meal")) -> Light meal | T10: =IF(AND(Flights[[#This Row],[Airline]]="US Airways", Flights[[#This Row],[Meal]]="Full Meal"), "Yes", "No") -> No | U10: 0.84375 | V10: -6 | W10: =IF(Flights[[#This Row],[Arrival Delay]] = "", "Cancelled", IF(Flights[[#This Row],[Arrival Delay]]>15, "Delayed", "On time")) -> On time | X10: =IF(Flights[[#This Row],[Status]]<>"Delayed","", IF(Flights[[#This Row],[Arrival Delay]]>120, "Severe", IF(Flights[[#This Row],[Arrival Delay]]>60, "Major", "Moderate"))) | Y10: FALSE | AA10: =IF(OR(AND(Flights[[#This Row],[Status]]="Cancelled", Flights[[#This Row],[Cancellation Reason]]="Airline/Carrier"), Flights[[#This Row],[Delay Type]]="Severe"), "Yes", "No") -> No
A11: 42005 | B11: =WEEKNUM(Flights[[#This Row],[Date]], 1) -> 1 | C11: =WEEKDAY(Flights[[#This Row],[Date]],1) -> 5 | D11: AA219 | E11: American Airlines | F11: LAX | G11: SFO | H11: =_xlfn.XLOOKUP(Flights[[#This Row],[Destination]], Airports!$A$2:$A$78, Airports!$D$2:$D$78) -> San Francisco | I11: {=_xlfn.XLOOKUP(Flights[[#This Row],[Destination]],_xlfn._TRO_TRAILING( Airports!A:A),_xlfn._TRO_TRAILING( Airports!E:E), "Not found")} -> CA | J11: 0.75 | K11: =HOUR(Flights[[#This Row],[Scheduled Departure]]) -> 18 | L11: 0.74791667 | M11: =(L11-J11)*24*60 -> -3 | N11: =Flights[[#This Row],[Length (min)]]/60 -> 1.2666667 | O11: 76 | P11: 337 | Q11: =IFERROR(Flights[[#This Row],[Distance]]/Flights[[#This Row],[Length (hr)]], "") -> 266.05263 | R11: 0.80555556 | S11: =IF(Flights[[#This Row],[Length (hr)]]<2, "No meal", IF(Flights[[#This Row],[Length (hr)]]<3.5, "Light meal", "Full meal")) -> No meal | T11: =IF(AND(Flights[[#This Row],[Airline]]="US Airways", Flights[[#This Row],[Meal]]="Full Meal"), "Yes", "No") -> No | U11: 0.80069444 | V11: -7 | W11: =IF(Flights[[#This Row],[Arrival Delay]] = "", "Cancelled", IF(Flights[[#This Row],[Arrival Delay]]>15, "Delayed", "On time")) -> On time | X11: =IF(Flights[[#This Row],[Status]]<>"Delayed","", IF(Flights[[#This Row],[Arrival Delay]]>120, "Severe", IF(Flights[[#This Row],[Arrival Delay]]>60, "Major", "Moderate"))) | Y11: FALSE | AA11: =IF(OR(AND(Flights[[#This Row],[Status]]="Cancelled", Flights[[#This Row],[Cancellation Reason]]="Airline/Carrier"), Flights[[#This Row],[Delay Type]]="Severe"), "Yes", "No") -> No
A12: 42005 | B12: =WEEKNUM(Flights[[#This Row],[Date]], 1) -> 1 | C12: =WEEKDAY(Flights[[#This Row],[Date]],1) -> 5 | D12: NK310 | E12: Spirit | F12: LAX | G12: FLL | H12: =_xlfn.XLOOKUP(Flights[[#This Row],[Destination]], Airports!$A$2:$A$78, Airports!$D$2:$D$78) -> Fort Lauderdale | I12: {=_xlfn.XLOOKUP(Flights[[#This Row],[Destination]],_xlfn._TRO_TRAILING( Airports!A:A),_xlfn._TRO_TRAILING( Airports!E:E), "Not found")} -> FL | J12: 0.875 | K12: =HOUR(Flights[[#This Row],[Scheduled Departure]]) -> 21 | L12: 0.88055556 | M12: =(L12-J12)*24*60 -> 8 | N12: =Flights[[#This Row],[Length (min)]]/60 -> 4.7666667 | O12: 286 | P12: 2342 | Q12: =IFERROR(Flights[[#This Row],[Distance]]/Flights[[#This Row],[Length (hr)]], "") -> 491.32867 | R12: 0.19513889 | S12: =IF(Flights[[#This Row],[Length (hr)]]<2, "No meal", IF(Flights[[#This Row],[Length (hr)]]<3.5, "Light meal", "Full meal")) -> Full meal | T12: =IF(AND(Flights[[#This Row],[Airline]]="US Airways", Flights[[#This Row],[Meal]]="Full Meal"), "Yes", "No") -> No | U12: 0.20416667 | V12: 13 | W12: =IF(Flights[[#This Row],[Arrival Delay]] = "", "Cancelled", IF(Flights[[#This Row],[Arrival Delay]]>15, "Delayed", "On time")) -> On time | X12: =IF(Flights[[#This Row],[Status]]<>"Delayed","", IF(Flights[[#This Row],[Arrival Delay]]>120, "Severe", IF(Flights[[#This Row],[Arrival Delay]]>60, "Major", "Moderate"))) | Y12: FALSE | AA12: =IF(OR(AND(Flights[[#This Row],[Status]]="Cancelled", Flights[[#This Row],[Cancellation Reason]]="Airline/Carrier"), Flights[[#This Row],[Delay Type]]="Severe"), "Yes", "No") -> No
A13: 42005 | B13: =WEEKNUM(Flights[[#This Row],[Date]], 1) -> 1 | C13: =WEEKDAY(Flights[[#This Row],[Date]],1) -> 5 | D13: OO2578 | E13: Skywest | F13: LAX | G13: SJC | H13: =_xlfn.XLOOKUP(Flights[[#This Row],[Destination]], Airports!$A$2:$A$78, Airports!$D$2:$D$78) -> San Jose | I13: {=_xlfn.XLOOKUP(Flights[[#This Row],[Destination]],_xlfn._TRO_TRAILING( Airports!A:A),_xlfn._TRO_TRAILING( Airports!E:E), "Not found")} -> CA | J13: 0.89236111 | K13: =HOUR(Flights[[#This Row],[Scheduled Departure]]) -> 21 | L13: 0.91736111 | M13: =(L13-J13)*24*60 -> 36 | N13: =Flights[[#This Row],[Length (min)]]/60 -> 1.0833333 | O13: 65 | P13: 308 | Q13: =IFERROR(Flights[[#This Row],[Distance]]/Flights[[#This Row],[Length (hr)]], "") -> 284.30769 | R13: 0.94097222 | S13: =IF(Flights[[#This Row],[Length (hr)]]<2, "No meal", IF(Flights[[#This Row],[Length (hr)]]<3.5, "Light meal", "Full meal")) -> No meal | T13: =IF(AND(Flights[[#This Row],[Airline]]="US Airways", Flights[[#This Row],[Meal]]="Full Meal"), "Yes", "No") -> No | U13: 0.9625 | V13: 31 | W13: =IF(Flights[[#This Row],[Arrival Delay]] = "", "Cancelled", IF(Flights[[#This Row],[Arrival Delay]]>15, "Delayed", "On time")) -> Delayed | X13: =IF(Flights[[#This Row],[Status]]<>"Delayed","", IF(Flights[[#This Row],[Arrival Delay]]>120, "Severe", IF(Flights[[#This Row],[Arrival Delay]]>60, "Major", "Moderate"))) -> Moderate | Y13: FALSE | AA13: =IF(OR(AND(Flights[[#This Row],[Status]]="Cancelled", Flights[[#This Row],[Cancellation Reason]]="Airline/Carrier"), Flights[[#This Row],[Delay Type]]="Severe"), "Yes", "No") -> No
... A74: 42010 | B74: =WEEKNUM(Flights[[#This Row],[Date]], 1) -> 2 | C74: =WEEKDAY(Flights[[#This Row],[Date]],1) -> 3 | D74: AA247 | E74: American Airlines | F74: LAX | G74: KOA | H74: =_xlfn.XLOOKUP(Flights[[#This Row],[Destination]], Airports!$A$2:$A$78, Airports!$D$2:$D$78) -> Kona | I74: {=_xlfn.XLOOKUP(Flights[[#This Row],[Destination]],_xlfn._TRO_TRAILING( Airports!A:A),_xlfn._TRO_TRAILING( Airports!E:E), "Not found")} -> HI | J74: 0.71527778 | K74: =HOUR(Flights[[#This Row],[Scheduled Departure]]) -> 17 | L74: 0.70902778 | M74: =(L74-J74)*24*60 -> -9 | N74: =Flights[[#This Row],[Length (min)]]/60 -> 5.9666667 | O74: 358 | P74: 2504 | Q74: =IFERROR(Flights[[#This Row],[Distance]]/Flights[[#This Row],[Length (hr)]], "") -> 419.6648 | R74: 0.87916667 | S74: =IF(Flights[[#This Row],[Length (hr)]]<2, "No meal", IF(Flights[[#This Row],[Length (hr)]]<3.5, "Light meal", "Full meal")) -> Full meal | T74: =IF(AND(Flights[[#This Row],[Airline]]="US Airways", Flights[[#This Row],[Meal]]="Full Meal"), "Yes", "No") -> No | U74: 0.87430556 | V74: -7 | W74: =IF(Flights[[#This Row],[Arrival Delay]] = "", "Cancelled", IF(Flights[[#This Row],[Arrival Delay]]>15, "Delayed", "On time")) -> On time | X74: =IF(Flights[[#This Row],[Status]]<>"Delayed","", IF(Flights[[#This Row],[Arrival Delay]]>120, "Severe", IF(Flights[[#This Row],[Arrival Delay]]>60, "Major", "Moderate"))) | Y74: FALSE | AA74: =IF(OR(AND(Flights[[#This Row],[Status]]="Cancelled", Flights[[#This Row],[Cancellation Reason]]="Airline/Carrier"), Flights[[#This Row],[Delay Type]]="Severe"), "Yes", "No") -> No
A75: 42010 | B75: =WEEKNUM(Flights[[#This Row],[Date]], 1) -> 2 | C75: =WEEKDAY(Flights[[#This Row],[Date]],1) -> 3 | D75: OO4678 | E75: Skywest | F75: LAX | G75: BOI | H75: =_xlfn.XLOOKUP(Flights[[#This Row],[Destination]], Airports!$A$2:$A$78, Airports!$D$2:$D$78) -> Boise | I75: {=_xlfn.XLOOKUP(Flights[[#This Row],[Destination]],_xlfn._TRO_TRAILING( Airports!A:A),_xlfn._TRO_TRAILING( Airports!E:E), "Not found")} -> ID | J75: 0.77083333 | K75: =HOUR(Flights[[#This Row],[Scheduled Departure]]) -> 18 | L75: 0 | M75: =(L75-J75)*24*60 -> -1110 | N75: =Flights[[#This Row],[Length (min)]]/60 -> 0 | P75: 674 | Q75: =IFERROR(Flights[[#This Row],[Distance]]/Flights[[#This Row],[Length (hr)]], "") | R75: 0.89791667 | S75: =IF(Flights[[#This Row],[Length (hr)]]<2, "No meal", IF(Flights[[#This Row],[Length (hr)]]<3.5, "Light meal", "Full meal")) -> No meal | T75: =IF(AND(Flights[[#This Row],[Airline]]="US Airways", Flights[[#This Row],[Meal]]="Full Meal"), "Yes", "No") -> No | U75: 0 | W75: =IF(Flights[[#This Row],[Arrival Delay]] = "", "Cancelled", IF(Flights[[#This Row],[Arrival Delay]]>15, "Delayed", "On time")) -> Cancelled | X75: =IF(Flights[[#This Row],[Status]]<>"Delayed","", IF(Flights[[#This Row],[Arrival Delay]]>120, "Severe", IF(Flights[[#This Row],[Arrival Delay]]>60, "Major", "Moderate"))) | Y75: TRUE | Z75: Weather | AA75: =IF(OR(AND(Flights[[#This Row],[Status]]="Cancelled", Flights[[#This Row],[Cancellation Reason]]="Airline/Carrier"), Flights[[#This Row],[Delay Type]]="Severe"), "Yes", "No") -> No
A76: 42010 | B76: =WEEKNUM(Flights[[#This Row],[Date]], 1) -> 2 | C76: =WEEKDAY(Flights[[#This Row],[Date]],1) -> 3 | D76: AA1410 | E76: American Airlines | F76: LAX | G76: LAS | H76: =_xlfn.XLOOKUP(Flights[[#This Row],[Destination]], Airports!$A$2:$A$78, Airports!$D$2:$D$78) -> Las Vegas | I76: {=_xlfn.XLOOKUP(Flights[[#This Row],[Destination]],_xlfn._TRO_TRAILING( Airports!A:A),_xlfn._TRO_TRAILING( Airports!E:E), "Not found")} -> NV | J76: 0.93333333 | K76: =HOUR(Flights[[#This Row],[Scheduled Departure]]) -> 22 | L76: 0.92916667 | M76: =(L76-J76)*24*60 -> -6 | N76: =Flights[[#This Row],[Length (min)]]/60 -> 1.0666667 | O76: 64 | P76: 236 | Q76: =IFERROR(Flights[[#This Row],[Distance]]/Flights[[#This Row],[Length (hr)]], "") -> 221.25 | R76: 0.98263889 | S76: =IF(Flights[[#This Row],[Length (hr)]]<2, "No meal", IF(Flights[[#This Row],[Length (hr)]]<3.5, "Light meal", "Full meal")) -> No meal | T76: =IF(AND(Flights[[#This Row],[Airline]]="US Airways", Flights[[#This Row],[Meal]]="Full Meal"), "Yes", "No") -> No | U76: 0.97361111 | V76: -13 | W76: =IF(Flights[[#This Row],[Arrival Delay]] = "", "Cancelled", IF(Flights[[#This Row],[Arrival Delay]]>15, "Delayed", "On time")) -> On time | X76: =IF(Flights[[#This Row],[Status]]<>"Delayed","", IF(Flights[[#This Row],[Arrival Delay]]>120, "Severe", IF(Flights[[#This Row],[Arrival Delay]]>60, "Major", "Moderate"))) | Y76: FALSE | AA76: =IF(OR(AND(Flights[[#This Row],[Status]]="Cancelled", Flights[[#This Row],[Cancellation Reason]]="Airline/Carrier"), Flights[[#This Row],[Delay Type]]="Severe"), "Yes", "No") -> No
A77: 42010 | B77: =WEEKNUM(Flights[[#This Row],[Date]], 1) -> 2 | C77: =WEEKDAY(Flights[[#This Row],[Date]],1) -> 3 | D77: B6688 | E77: JetBlue | F77: LAX | G77: BOS | H77: =_xlfn.XLOOKUP(Flights[[#This Row],[Destination]], Airports!$A$2:$A$78, Airports!$D$2:$D$78) -> Boston | I77: {=_xlfn.XLOOKUP(Flights[[#This Row],[Destination]],_xlfn._TRO_TRAILING( Airports!A:A),_xlfn._TRO_TRAILING( Airports!E:E), "Not found")} -> MA | J77: 0.99236111 | K77: =HOUR(Flights[[#This Row],[Scheduled Departure]]) -> 23 | L77: 0.03125 | M77: =(L77-J77)*24*60 -> -1384 | N77: =Flights[[#This Row],[Length (min)]]/60 -> 5.05 | O77: 303 | P77: 2611 | Q77: =IFERROR(Flights[[#This Row],[Distance]]/Flights[[#This Row],[Length (hr)]], "") -> 517.0297 | R77: 0.33958333 | S77: =IF(Flights[[#This Row],[Length (hr)]]<2, "No meal", IF(Flights[[#This Row],[Length (hr)]]<3.5, "Light meal", "Full meal")) -> Full meal | T77: =IF(AND(Flights[[#This Row],[Airline]]="US Airways", Flights[[#This Row],[Meal]]="Full Meal"), "Yes", "No") -> No | U77: 0.36666667 | V77: 39 | W77: =IF(Flights[[#This Row],[Arrival Delay]] = "", "Cancelled", IF(Flights[[#This Row],[Arrival Delay]]>15, "Delayed", "On time")) -> Delayed | X77: =IF(Flights[[#This Row],[Status]]<>"Delayed","", IF(Flights[[#This Row],[Arrival Delay]]>120, "Severe", IF(Flights[[#This Row],[Arrival Delay]]>60, "Major", "Moderate"))) -> Moderate | Y77: FALSE | AA77: =IF(OR(AND(Flights[[#This Row],[Status]]="Cancelled", Flights[[#This Row],[Cancellation Reason]]="Airline/Carrier"), Flights[[#This Row],[Delay Type]]="Severe"), "Yes", "No") -> No
A78: 42011 | B78: =WEEKNUM(Flights[[#This Row],[Date]], 1) -> 2 | C78: =WEEKDAY(Flights[[#This Row],[Date]],1) -> 4 | D78: AA387 | E78: American Airlines | F78: LAX | G78: AUS | H78: =_xlfn.XLOOKUP(Flights[[#This Row],[Destination]], Airports!$A$2:$A$78, Airports!$D$2:$D$78) -> Austin | I78: {=_xlfn.XLOOKUP(Flights[[#This Row],[Destination]],_xlfn._TRO_TRAILING( Airports!A:A),_xlfn._TRO_TRAILING( Airports!E:E), "Not found")} -> TX | J78: 0.26736111 | K78: =HOUR(Flights[[#This Row],[Scheduled Departure]]) -> 6 | L78: 0.2625 | M78: =(L78-J78)*24*60 -> -7 | N78: =Flights[[#This Row],[Length (min)]]/60 -> 3.1 | O78: 186 | P78: 1242 | Q78: =IFERROR(Flights[[#This Row],[Distance]]/Flights[[#This Row],[Length (hr)]], "") -> 400.64516 | R78: 0.47291667 | S78: =IF(Flights[[#This Row],[Length (hr)]]<2, "No meal", IF(Flights[[#This Row],[Length (hr)]]<3.5, "Light meal", "Full meal")) -> Light meal | T78: =IF(AND(Flights[[#This Row],[Airline]]="US Airways", Flights[[#This Row],[Meal]]="Full Meal"), "Yes", "No") -> No | U78: 0.475 | V78: 3 | W78: =IF(Flights[[#This Row],[Arrival Delay]] = "", "Cancelled", IF(Flights[[#This Row],[Arrival Delay]]>15, "Delayed", "On time")) -> On time | X78: =IF(Flights[[#This Row],[Status]]<>"Delayed","", IF(Flights[[#This Row],[Arrival Delay]]>120, "Severe", IF(Flights[[#This Row],[Arrival Delay]]>60, "Major", "Moderate"))) | Y78: FALSE | AA78: =IF(OR(AND(Flights[[#This Row],[Status]]="Cancelled", Flights[[#This Row],[Cancellation Reason]]="Airline/Carrier"), Flights[[#This Row],[Delay Type]]="Severe"), "Yes", "No") -> No
A79: 42011 | B79: =WEEKNUM(Flights[[#This Row],[Date]], 1) -> 2 | C79: =WEEKDAY(Flights[[#This Row],[Date]],1) -> 4 | D79: WN2864 | E79: Southwest | F79: LAX | G79: BWI | H79: =_xlfn.XLOOKUP(Flights[[#This Row],[Destination]], Airports!$A$2:$A$78, Airports!$D$2:$D$78) -> Baltimore | I79: {=_xlfn.XLOOKUP(Flights[[#This Row],[Destination]],_xlfn._TRO_TRAILING( Airports!A:A),_xlfn._TRO_TRAILING( Airports!E:E), "Not found")} -> MD | J79: 0.29166667 | K79: =HOUR(Flights[[#This Row],[Scheduled Departure]]) -> 7 | L79: 0.29722222 | M79: =(L79-J79)*24*60 -> 8 | N79: =Flights[[#This Row],[Length (min)]]/60 -> 4.7166667 | O79: 283 | P79: 2329 | Q79: =IFERROR(Flights[[#This Row],[Distance]]/Flights[[#This Row],[Length (hr)]], "") -> 493.78092 | R79: 0.62152778 | S79: =IF(Flights[[#This Row],[Length (hr)]]<2, "No meal", IF(Flights[[#This Row],[Length (hr)]]<3.5, "Light meal", "Full meal")) -> Full meal | T79: =IF(AND(Flights[[#This Row],[Airline]]="US Airways", Flights[[#This Row],[Meal]]="Full Meal"), "Yes", "No") -> No | U79: 0.61875 | V79: -4 | W79: =IF(Flights[[#This Row],[Arrival Delay]] = "", "Cancelled", IF(Flights[[#This Row],[Arrival Delay]]>15, "Delayed", "On time")) -> On time | X79: =IF(Flights[[#This Row],[Status]]<>"Delayed","", IF(Flights[[#This Row],[Arrival Delay]]>120, "Severe", IF(Flights[[#This Row],[Arrival Delay]]>60, "Major", "Moderate"))) | Y79: FALSE | AA79: =IF(OR(AND(Flights[[#This Row],[Status]]="Cancelled", Flights[[#This Row],[Cancellation Reason]]="Airline/Carrier"), Flights[[#This Row],[Delay Type]]="Severe"), "Yes", "No") -> No
A80: 42011 | B80: =WEEKNUM(Flights[[#This Row],[Date]], 1) -> 2 | C80: =WEEKDAY(Flights[[#This Row],[Date]],1) -> 4 | D80: UA1203 | E80: United | F80: LAX | G80: SFO | H80: =_xlfn.XLOOKUP(Flights[[#This Row],[Destination]], Airports!$A$2:$A$78, Airports!$D$2:$D$78) -> San Francisco | I80: {=_xlfn.XLOOKUP(Flights[[#This Row],[Destination]],_xlfn._TRO_TRAILING( Airports!A:A),_xlfn._TRO_TRAILING( Airports!E:E), "Not found")} -> CA | J80: 0.33333333 | K80: =HOUR(Flights[[#This Row],[Scheduled Departure]]) -> 8 | L80: 0.33680556 | M80: =(L80-J80)*24*60 -> 5 | N80: =Flights[[#This Row],[Length (min)]]/60 -> 1.25 | O80: 75 | P80: 337 | Q80: =IFERROR(Flights[[#This Row],[Distance]]/Flights[[#This Row],[Length (hr)]], "") -> 269.6 | R80: 0.39930556 | S80: =IF(Flights[[#This Row],[Length (hr)]]<2, "No meal", IF(Flights[[#This Row],[Length (hr)]]<3.5, "Light meal", "Full meal")) -> No meal | T80: =IF(AND(Flights[[#This Row],[Airline]]="US Airways", Flights[[#This Row],[Meal]]="Full Meal"), "Yes", "No") -> No | U80: 0.38888889 | V80: -15 | W80: =IF(Flights[[#This Row],[Arrival Delay]] = "", "Cancelled", IF(Flights[[#This Row],[Arrival Delay]]>15, "Delayed", "On time")) -> On time | X80: =IF(Flights[[#This Row],[Status]]<>"Delayed","", IF(Flights[[#This Row],[Arrival Delay]]>120, "Severe", IF(Flights[[#This Row],[Arrival Delay]]>60, "Major", "Moderate"))) | Y80: FALSE | AA80: =IF(OR(AND(Flights[[#This Row],[Status]]="Cancelled", Flights[[#This Row],[Cancellation Reason]]="Airline/Carrier"), Flights[[#This Row],[Delay Type]]="Severe"), "Yes", "No") -> No
A81: 42011 | B81: =WEEKNUM(Flights[[#This Row],[Date]], 1) -> 2 | C81: =WEEKDAY(Flights[[#This Row],[Date]],1) -> 4 | D81: UA1658 | E81: United | F81: LAX | G81: DEN | H81: =_xlfn.XLOOKUP(Flights[[#This Row],[Destination]], Airports!$A$2:$A$78, Airports!$D$2:$D$78) -> Denver | I81: {=_xlfn.XLOOKUP(Flights[[#This Row],[Destination]],_xlfn._TRO_TRAILING( Airports!A:A),_xlfn._TRO_TRAILING( Airports!E:E), "Not found")} -> CO | J81: 0.34375 | K81: =HOUR(Flights[[#This Row],[Scheduled Departure]]) -> 8 | L81: 0.35 | M81: =(L81-J81)*24*60 -> 9 | N81: =Flights[[#This Row],[Length (min)]]/60 -> 3.5666667 | O81: 214 | P81: 862 | Q81: =IFERROR(Flights[[#This Row],[Distance]]/Flights[[#This Row],[Length (hr)]], "") -> 241.68224 | R81: 0.48611111 | S81: =IF(Flights[[#This Row],[Length (hr)]]<2, "No meal", IF(Flights[[#This Row],[Length (hr)]]<3.5, "Light meal", "Full meal")) -> Full meal | T81: =IF(AND(Flights[[#This Row],[Airline]]="US Airways", Flights[[#This Row],[Meal]]="Full Meal"), "Yes", "No") -> No | U81: 0.54027778 | V81: 78 | W81: =IF(Flights[[#This Row],[Arrival Delay]] = "", "Cancelled", IF(Flights[[#This Row],[Arrival Delay]]>15, "Delayed", "On time")) -> Delayed | X81: =IF(Flights[[#This Row],[Status]]<>"Delayed","", IF(Flights[[#This Row],[Arrival Delay]]>120, "Severe", IF(Flights[[#This Row],[Arrival Delay]]>60, "Major", "Moderate"))) -> Major | Y81: FALSE | AA81: =IF(OR(AND(Flights[[#This Row],[Status]]="Cancelled", Flights[[#This Row],[Cancellation Reason]]="Airline/Carrier"), Flights[[#This Row],[Delay Type]]="Severe"), "Yes", "No") -> No
A82: 42011 | B82: =WEEKNUM(Flights[[#This Row],[Date]], 1) -> 2 | C82: =WEEKDAY(Flights[[#This Row],[Date]],1) -> 4 | D82: AA265 | E82: American Airlines | F82: LAX | G82: LIH | H82: =_xlfn.XLOOKUP(Flights[[#This Row],[Destination]], Airports!$A$2:$A$78, Airports!$D$2:$D$78) -> Lihue | I82: {=_xlfn.XLOOKUP(Flights[[#This Row],[Destination]],_xlfn._TRO_TRAILING( Airports!A:A),_xlfn._TRO_TRAILING( Airports!E:E), "Not found")} -> HI | J82: 0.38541667 | K82: =HOUR(Flights[[#This Row],[Scheduled Departure]]) -> 9 | L82: 0.38055556 | M82: =(L82-J82)*24*60 -> -7 | N82: =Flights[[#This Row],[Length (min)]]/60 -> 6.4833333 | O82: 389 | P82: 2615 | Q82: =IFERROR(Flights[[#This Row],[Distance]]/Flights[[#This Row],[Length (hr)]], "") -> 403.3419 | R82: 0.56597222 | S82: =IF(Flights[[#This Row],[Length (hr)]]<2, "No meal", IF(Flights[[#This Row],[Length (hr)]]<3.5, "Light meal", "Full meal")) -> Full meal | T82: =IF(AND(Flights[[#This Row],[Airline]]="US Airways", Flights[[#This Row],[Meal]]="Full Meal"), "Yes", "No") -> No | U82: 0.56736111 | V82: 2 | W82: =IF(Flights[[#This Row],[Arrival Delay]] = "", "Cancelled", IF(Flights[[#This Row],[Arrival Delay]]>15, "Delayed", "On time")) -> On time | X82: =IF(Flights[[#This Row],[Status]]<>"Delayed","", IF(Flights[[#This Row],[Arrival Delay]]>120, "Severe", IF(Flights[[#This Row],[Arrival Delay]]>60, "Major", "Moderate"))) | Y82: FALSE | AA82: =IF(OR(AND(Flights[[#This Row],[Status]]="Cancelled", Flights[[#This Row],[Cancellation Reason]]="Airline/Carrier"), Flights[[#This Row],[Delay Type]]="Severe"), "Yes", "No") -> No
A83: 42011 | B83: =WEEKNUM(Flights[[#This Row],[Date]], 1) -> 2 | C83: =WEEKDAY(Flights[[#This Row],[Date]],1) -> 4 | D83: WN2152 | E83: Southwest | F83: LAX | G83: SFO | H83: =_xlfn.XLOOKUP(Flights[[#This Row],[Destination]], Airports!$A$2:$A$78, Airports!$D$2:$D$78) -> San Francisco | I83: {=_xlfn.XLOOKUP(Flights[[#This Row],[Destination]],_xlfn._TRO_TRAILING( Airports!A:A),_xlfn._TRO_TRAILING( Airports!E:E), "Not found")} -> CA | J83: 0.40972222 | K83: =HOUR(Flights[[#This Row],[Scheduled Departure]]) -> 9 | L83: 0.40902778 | M83: =(L83-J83)*24*60 -> -1 | N83: =Flights[[#This Row],[Length (min)]]/60 -> 1.1 | O83: 66 | P83: 337 | Q83: =IFERROR(Flights[[#This Row],[Distance]]/Flights[[#This Row],[Length (hr)]], "") -> 306.36364 | R83: 0.47222222 | S83: =IF(Flights[[#This Row],[Length (hr)]]<2, "No meal", IF(Flights[[#This Row],[Length (hr)]]<3.5, "Light meal", "Full meal")) -> No meal | T83: =IF(AND(Flights[[#This Row],[Airline]]="US Airways", Flights[[#This Row],[Meal]]="Full Meal"), "Yes", "No") -> No | U83: 0.45486111 | V83: -25 | W83: =IF(Flights[[#This Row],[Arrival Delay]] = "", "Cancelled", IF(Flights[[#This Row],[Arrival Delay]]>15, "Delayed", "On time")) -> On time | X83: =IF(Flights[[#This Row],[Status]]<>"Delayed","", IF(Flights[[#This Row],[Arrival Delay]]>120, "Severe", IF(Flights[[#This Row],[Arrival Delay]]>60, "Major", "Moderate"))) | Y83: FALSE | AA83: =IF(OR(AND(Flights[[#This Row],[Status]]="Cancelled", Flights[[#This Row],[Cancellation Reason]]="Airline/Carrier"), Flights[[#This Row],[Delay Type]]="Severe"), "Yes", "No") -> No
A84: 42011 | B84: =WEEKNUM(Flights[[#This Row],[Date]], 1) -> 2 | C84: =WEEKDAY(Flights[[#This Row],[Date]],1) -> 4 | D84: WN4304 | E84: Southwest | F84: LAX | G84: SJC | H84: =_xlfn.XLOOKUP(Flights[[#This Row],[Destination]], Airports!$A$2:$A$78, Airports!$D$2:$D$78) -> San Jose | I84: {=_xlfn.XLOOKUP(Flights[[#This Row],[Destination]],_xlfn._TRO_TRAILING( Airports!A:A),_xlfn._TRO_TRAILING( Airports!E:E), "Not found")} -> CA | J84: 0.45833333 | K84: =HOUR(Flights[[#This Row],[Scheduled Departure]]) -> 11 | L84: 0.46111111 | M84: =(L84-J84)*24*60 -> 4 | N84: =Flights[[#This Row],[Length (min)]]/60 -> 1.05 | O84: 63 | P84: 308 | Q84: =IFERROR(Flights[[#This Row],[Distance]]/Flights[[#This Row],[Length (hr)]], "") -> 293.33333 | R84: 0.50347222 | S84: =IF(Flights[[#This Row],[Length (hr)]]<2, "No meal", IF(Flights[[#This Row],[Length (hr)]]<3.5, "Light meal", "Full meal")) -> No meal | T84: =IF(AND(Flights[[#This Row],[Airline]]="US Airways", Flights[[#This Row],[Meal]]="Full Meal"), "Yes", "No") -> No | U84: 0.50486111 | V84: 2 | W84: =IF(Flights[[#This Row],[Arrival Delay]] = "", "Cancelled", IF(Flights[[#This Row],[Arrival Delay]]>15, "Delayed", "On time")) -> On time | X84: =IF(Flights[[#This Row],[Status]]<>"Delayed","", IF(Flights[[#This Row],[Arrival Delay]]>120, "Severe", IF(Flights[[#This Row],[Arrival Delay]]>60, "Major", "Moderate"))) | Y84: FALSE | AA84: =IF(OR(AND(Flights[[#This Row],[Status]]="Cancelled", Flights[[#This Row],[Cancellation Reason]]="Airline/Carrier"), Flights[[#This Row],[Delay Type]]="Severe"), "Yes", "No") -> No
A85: 42011 | B85: =WEEKNUM(Flights[[#This Row],[Date]], 1) -> 2 | C85: =WEEKDAY(Flights[[#This Row],[Date]],1) -> 4 | D85: OO4825 | E85: Skywest | F85: LAX | G85: SJC | H85: =_xlfn.XLOOKUP(Flights[[#This Row],[Destination]], Airports!$A$2:$A$78, Airports!$D$2:$D$78) -> San Jose | I85: {=_xlfn.XLOOKUP(Flights[[#This Row],[Destination]],_xlfn._TRO_TRAILING( Airports!A:A),_xlfn._TRO_TRAILING( Airports!E:E), "Not found")} -> CA | J85: 0.52777778 | K85: =HOUR(Flights[[#This Row],[Scheduled Departure]]) -> 12 | L85: 0.53472222 | M85: =(L85-J85)*24*60 -> 10 | N85: =Flights[[#This Row],[Length (min)]]/60 -> 1.1166667 | O85: 67 | P85: 308 | Q85: =IFERROR(Flights[[#This Row],[Distance]]/Flights[[#This Row],[Length (hr)]], "") -> 275.8209 | R85: 0.57986111 | S85: =IF(Flights[[#This Row],[Length (hr)]]<2, "No meal", IF(Flights[[#This Row],[Length (hr)]]<3.5, "Light meal", "Full meal")) -> No meal | T85: =IF(AND(Flights[[#This Row],[Airline]]="US Airways", Flights[[#This Row],[Meal]]="Full Meal"), "Yes", "No") -> No | U85: 0.58125 | V85: 2 | W85: =IF(Flights[[#This Row],[Arrival Delay]] = "", "Cancelled", IF(Flights[[#This Row],[Arrival Delay]]>15, "Delayed", "On time")) -> On time | X85: =IF(Flights[[#This Row],[Status]]<>"Delayed","", IF(Flights[[#This Row],[Arrival Delay]]>120, "Severe", IF(Flights[[#This Row],[Arrival Delay]]>60, "Major", "Moderate"))) | Y85: FALSE | AA85: =IF(OR(AND(Flights[[#This Row],[Status]]="Cancelled", Flights[[#This Row],[Cancellation Reason]]="Airline/Carrier"), Flights[[#This Row],[Delay Type]]="Severe"), "Yes", "No") -> No
A86: 42011 | B86: =WEEKNUM(Flights[[#This Row],[Date]], 1) -> 2 | C86: =WEEKDAY(Flights[[#This Row],[Date]],1) -> 4 | D86: OO6496 | E86: Skywest | F86: LAX | G86: COS | H86: =_xlfn.XLOOKUP(Flights[[#This Row],[Destination]], Airports!$A$2:$A$78, Airports!$D$2:$D$78) -> Colorado Springs | I86: {=_xlfn.XLOOKUP(Flights[[#This Row],[Destination]],_xlfn._TRO_TRAILING( Airports!A:A),_xlfn._TRO_TRAILING( Airports!E:E), "Not found")} -> CO | J86: 0.79861111 | K86: =HOUR(Flights[[#This Row],[Scheduled Departure]]) -> 19 | L86: 0.79375 | M86: =(L86-J86)*24*60 -> -7 | N86: =Flights[[#This Row],[Length (min)]]/60 -> 2.4666667 | O86: 148 | P86: 833 | Q86: =IFERROR(Flights[[#This Row],[Distance]]/Flights[[#This Row],[Length (hr)]], "") -> 337.7027 | R86: 0.93194444 | S86: =IF(Flights[[#This Row],[Length (hr)]]<2, "No meal", IF(Flights[[#This Row],[Length (hr)]]<3.5, "Light meal", "Full meal")) -> Light meal | T86: =IF(AND(Flights[[#This Row],[Airline]]="US Airways", Flights[[#This Row],[Meal]]="Full Meal"), "Yes", "No") -> No | U86: 0.93819444 | V86: 9 | W86: =IF(Flights[[#This Row],[Arrival Delay]] = "", "Cancelled", IF(Flights[[#This Row],[Arrival Delay]]>15, "Delayed", "On time")) -> On time | X86: =IF(Flights[[#This Row],[Status]]<>"Delayed","", IF(Flights[[#This Row],[Arrival Delay]]>120, "Severe", IF(Flights[[#This Row],[Arrival Delay]]>60, "Major", "Moderate"))) | Y86: FALSE | AA86: =IF(OR(AND(Flights[[#This Row],[Status]]="Cancelled", Flights[[#This Row],[Cancellation Reason]]="Airline/Carrier"), Flights[[#This Row],[Delay Type]]="Severe"), "Yes", "No") -> No
A87: 42012 | B87: =WEEKNUM(Flights[[#This Row],[Date]], 1) -> 2 | C87: =WEEKDAY(Flights[[#This Row],[Date]],1) -> 5 | D87: WN4236 | E87: Southwest | F87: LAX | G87: OAK | H87: =_xlfn.XLOOKUP(Flights[[#This Row],[Destination]], Airports!$A$2:$A$78, Airports!$D$2:$D$78) -> Oakland | I87: {=_xlfn.XLOOKUP(Flights[[#This Row],[Destination]],_xlfn._TRO_TRAILING( Airports!A:A),_xlfn._TRO_TRAILING( Airports!E:E), "Not found")} -> CA | J87: 0.375 | K87: =HOUR(Flights[[#This Row],[Scheduled Departure]]) -> 9 | L87: 0.37361111 | M87: =(L87-J87)*24*60 -> -2 | N87: =Flights[[#This Row],[Length (min)]]/60 -> 1.0833333 | O87: 65 | P87: 337 | Q87: =IFERROR(Flights[[#This Row],[Distance]]/Flights[[#This Row],[Length (hr)]], "") -> 311.07692 | R87: 0.43055556 | S87: =IF(Flights[[#This Row],[Length (hr)]]<2, "No meal", IF(Flights[[#This Row],[Length (hr)]]<3.5, "Light meal", "Full meal")) -> No meal | T87: =IF(AND(Flights[[#This Row],[Airline]]="US Airways", Flights[[#This Row],[Meal]]="Full Meal"), "Yes", "No") -> No | U87: 0.41875 | V87: -17 | W87: =IF(Flights[[#This Row],[Arrival Delay]] = "", "Cancelled", IF(Flights[[#This Row],[Arrival Delay]]>15, "Delayed", "On time")) -> On time | X87: =IF(Flights[[#This Row],[Status]]<>"Delayed","", IF(Flights[[#This Row],[Arrival Delay]]>120, "Severe", IF(Flights[[#This Row],[Arrival Delay]]>60, "Major", "Moderate"))) | Y87: FALSE | AA87: =IF(OR(AND(Flights[[#This Row],[Status]]="Cancelled", Flights[[#This Row],[Cancellation Reason]]="Airline/Carrier"), Flights[[#This Row],[Delay Type]]="Severe"), "Yes", "No") -> No
... A95: 42012 | B95: =WEEKNUM(Flights[[#This Row],[Date]], 1) -> 2 | C95: =WEEKDAY(Flights[[#This Row],[Date]],1) -> 5 | D95: UA438 | E95: United | F95: LAX | G95: ORD | H95: =_xlfn.XLOOKUP(Flights[[#This Row],[Destination]], Airports!$A$2:$A$78, Airports!$D$2:$D$78) -> Chicago | I95: {=_xlfn.XLOOKUP(Flights[[#This Row],[Destination]],_xlfn._TRO_TRAILING( Airports!A:A),_xlfn._TRO_TRAILING( Airports!E:E), "Not found")} -> IL | J95: 0.71458333 | K95: =HOUR(Flights[[#This Row],[Scheduled Departure]]) -> 17 | L95: 0.71111111 | M95: =(L95-J95)*24*60 -> -5 | N95: =Flights[[#This Row],[Length (min)]]/60 -> 5.8166667 | O95: 349 | P95: 1744 | Q95: =IFERROR(Flights[[#This Row],[Distance]]/Flights[[#This Row],[Length (hr)]], "") -> 299.82808 | R95: 0.97222222 | S95: =IF(Flights[[#This Row],[Length (hr)]]<2, "No meal", IF(Flights[[#This Row],[Length (hr)]]<3.5, "Light meal", "Full meal")) -> Full meal | T95: =IF(AND(Flights[[#This Row],[Airline]]="US Airways", Flights[[#This Row],[Meal]]="Full Meal"), "Yes", "No") -> No | U95: 0.036805556 | V95: 93 | W95: =IF(Flights[[#This Row],[Arrival Delay]] = "", "Cancelled", IF(Flights[[#This Row],[Arrival Delay]]>15, "Delayed", "On time")) -> Delayed | X95: =IF(Flights[[#This Row],[Status]]<>"Delayed","", IF(Flights[[#This Row],[Arrival Delay]]>120, "Severe", IF(Flights[[#This Row],[Arrival Delay]]>60, "Major", "Moderate"))) -> Major | Y95: FALSE | AA95: =IF(OR(AND(Flights[[#This Row],[Status]]="Cancelled", Flights[[#This Row],[Cancellation Reason]]="Airline/Carrier"), Flights[[#This Row],[Delay Type]]="Severe"), "Yes", "No") -> No
A96: 42012 | B96: =WEEKNUM(Flights[[#This Row],[Date]], 1) -> 2 | C96: =WEEKDAY(Flights[[#This Row],[Date]],1) -> 5 | D96: OO2600 | E96: Skywest | F96: LAX | G96: RDM | H96: =_xlfn.XLOOKUP(Flights[[#This Row],[Destination]], Airports!$A$2:$A$78, Airports!$D$2:$D$78) -> Redmond | I96: {=_xlfn.XLOOKUP(Flights[[#This Row],[Destination]],_xlfn._TRO_TRAILING( Airports!A:A),_xlfn._TRO_TRAILING( Airports!E:E), "Not found")} -> OR | J96: 0.74583333 | K96: =HOUR(Flights[[#This Row],[Scheduled Departure]]) -> 17 | L96: 0 | M96: =(L96-J96)*24*60 -> -1074 | N96: =Flights[[#This Row],[Length (min)]]/60 -> 0 | P96: 726 | Q96: =IFERROR(Flights[[#This Row],[Distance]]/Flights[[#This Row],[Length (hr)]], "") | R96: 0.83263889 | S96: =IF(Flights[[#This Row],[Length (hr)]]<2, "No meal", IF(Flights[[#This Row],[Length (hr)]]<3.5, "Light meal", "Full meal")) -> No meal | T96: =IF(AND(Flights[[#This Row],[Airline]]="US Airways", Flights[[#This Row],[Meal]]="Full Meal"), "Yes", "No") -> No | U96: 0 | W96: =IF(Flights[[#This Row],[Arrival Delay]] = "", "Cancelled", IF(Flights[[#This Row],[Arrival Delay]]>15, "Delayed", "On time")) -> Cancelled | X96: =IF(Flights[[#This Row],[Status]]<>"Delayed","", IF(Flights[[#This Row],[Arrival Delay]]>120, "Severe", IF(Flights[[#This Row],[Arrival Delay]]>60, "Major", "Moderate"))) | Y96: TRUE | Z96: Weather | AA96: =IF(OR(AND(Flights[[#This Row],[Status]]="Cancelled", Flights[[#This Row],[Cancellation Reason]]="Airline/Carrier"), Flights[[#This Row],[Delay Type]]="Severe"), "Yes", "No") -> No
A97: 42012 | B97: =WEEKNUM(Flights[[#This Row],[Date]], 1) -> 2 | C97: =WEEKDAY(Flights[[#This Row],[Date]],1) -> 5 | D97: WN3588 | E97: Southwest | F97: LAX | G97: OAK | H97: =_xlfn.XLOOKUP(Flights[[#This Row],[Destination]], Airports!$A$2:$A$78, Airports!$D$2:$D$78) -> Oakland | I97: {=_xlfn.XLOOKUP(Flights[[#This Row],[Destination]],_xlfn._TRO_TRAILING( Airports!A:A),_xlfn._TRO_TRAILING( Airports!E:E), "Not found")} -> CA | J97: 0.76388889 | K97: =HOUR(Flights[[#This Row],[Scheduled Departure]]) -> 18 | L97: 0.76597222 | M97: =(L97-J97)*24*60 -> 3 | N97: =Flights[[#This Row],[Length (min)]]/60 -> 1.0666667 | O97: 64 | P97: 337 | Q97: =IFERROR(Flights[[#This Row],[Distance]]/Flights[[#This Row],[Length (hr)]], "") -> 315.9375 | R97: 0.81597222 | S97: =IF(Flights[[#This Row],[Length (hr)]]<2, "No meal", IF(Flights[[#This Row],[Length (hr)]]<3.5, "Light meal", "Full meal")) -> No meal | T97: =IF(AND(Flights[[#This Row],[Airline]]="US Airways", Flights[[#This Row],[Meal]]="Full Meal"), "Yes", "No") -> No | U97: 0.81041667 | V97: -8 | W97: =IF(Flights[[#This Row],[Arrival Delay]] = "", "Cancelled", IF(Flights[[#This Row],[Arrival Delay]]>15, "Delayed", "On time")) -> On time | X97: =IF(Flights[[#This Row],[Status]]<>"Delayed","", IF(Flights[[#This Row],[Arrival Delay]]>120, "Severe", IF(Flights[[#This Row],[Arrival Delay]]>60, "Major", "Moderate"))) | Y97: FALSE | AA97: =IF(OR(AND(Flights[[#This Row],[Status]]="Cancelled", Flights[[#This Row],[Cancellation Reason]]="Airline/Carrier"), Flights[[#This Row],[Delay Type]]="Severe"), "Yes", "No") -> No
A98: 42012 | B98: =WEEKNUM(Flights[[#This Row],[Date]], 1) -> 2 | C98: =WEEKDAY(Flights[[#This Row],[Date]],1) -> 5 | D98: WN816 | E98: Southwest | F98: LAX | G98: OAK | H98: =_xlfn.XLOOKUP(Flights[[#This Row],[Destination]], Airports!$A$2:$A$78, Airports!$D$2:$D$78) -> Oakland | I98: {=_xlfn.XLOOKUP(Flights[[#This Row],[Destination]],_xlfn._TRO_TRAILING( Airports!A:A),_xlfn._TRO_TRAILING( Airports!E:E), "Not found")} -> CA | J98: 0.81597222 | K98: =HOUR(Flights[[#This Row],[Scheduled Departure]]) -> 19 | L98: 0.81319444 | M98: =(L98-J98)*24*60 -> -4 | N98: =Flights[[#This Row],[Length (min)]]/60 -> 1.0666667 | O98: 64 | P98: 337 | Q98: =IFERROR(Flights[[#This Row],[Distance]]/Flights[[#This Row],[Length (hr)]], "") -> 315.9375 | R98: 0.86805556 | S98: =IF(Flights[[#This Row],[Length (hr)]]<2, "No meal", IF(Flights[[#This Row],[Length (hr)]]<3.5, "Light meal", "Full meal")) -> No meal | T98: =IF(AND(Flights[[#This Row],[Airline]]="US Airways", Flights[[#This Row],[Meal]]="Full Meal"), "Yes", "No") -> No | U98: 0.85763889 | V98: -15 | W98: =IF(Flights[[#This Row],[Arrival Delay]] = "", "Cancelled", IF(Flights[[#This Row],[Arrival Delay]]>15, "Delayed", "On time")) -> On time | X98: =IF(Flights[[#This Row],[Status]]<>"Delayed","", IF(Flights[[#This Row],[Arrival Delay]]>120, "Severe", IF(Flights[[#This Row],[Arrival Delay]]>60, "Major", "Moderate"))) | Y98: FALSE | AA98: =IF(OR(AND(Flights[[#This Row],[Status]]="Cancelled", Flights[[#This Row],[Cancellation Reason]]="Airline/Carrier"), Flights[[#This Row],[Delay Type]]="Severe"), "Yes", "No") -> No
A99: 42013 | B99: =WEEKNUM(Flights[[#This Row],[Date]], 1) -> 2 | C99: =WEEKDAY(Flights[[#This Row],[Date]],1) -> 6 | D99: UA1679 | E99: United | F99: LAX | G99: SFO | H99: =_xlfn.XLOOKUP(Flights[[#This Row],[Destination]], Airports!$A$2:$A$78, Airports!$D$2:$D$78) -> San Francisco | I99: {=_xlfn.XLOOKUP(Flights[[#This Row],[Destination]],_xlfn._TRO_TRAILING( Airports!A:A),_xlfn._TRO_TRAILING( Airports!E:E), "Not found")} -> CA | J99: 0.25 | K99: =HOUR(Flights[[#This Row],[Scheduled Departure]]) -> 6 | L99: 0.40625 | M99: =(L99-J99)*24*60 -> 225 | N99: =Flights[[#This Row],[Length (min)]]/60 -> 1.1166667 | O99: 67 | P99: 337 | Q99: =IFERROR(Flights[[#This Row],[Distance]]/Flights[[#This Row],[Length (hr)]], "") -> 301.79104 | R99: 0.31180556 | S99: =IF(Flights[[#This Row],[Length (hr)]]<2, "No meal", IF(Flights[[#This Row],[Length (hr)]]<3.5, "Light meal", "Full meal")) -> No meal | T99: =IF(AND(Flights[[#This Row],[Airline]]="US Airways", Flights[[#This Row],[Meal]]="Full Meal"), "Yes", "No") -> No | U99: 0.45277778 | V99: 203 | W99: =IF(Flights[[#This Row],[Arrival Delay]] = "", "Cancelled", IF(Flights[[#This Row],[Arrival Delay]]>15, "Delayed", "On time")) -> Delayed | X99: =IF(Flights[[#This Row],[Status]]<>"Delayed","", IF(Flights[[#This Row],[Arrival Delay]]>120, "Severe", IF(Flights[[#This Row],[Arrival Delay]]>60, "Major", "Moderate"))) -> Severe | Y99: FALSE | AA99: =IF(OR(AND(Flights[[#This Row],[Status]]="Cancelled", Flights[[#This Row],[Cancellation Reason]]="Airline/Carrier"), Flights[[#This Row],[Delay Type]]="Severe"), "Yes", "No") -> Yes
A100: 42013 | B100: =WEEKNUM(Flights[[#This Row],[Date]], 1) -> 2 | C100: =WEEKDAY(Flights[[#This Row],[Date]],1) -> 6 | D100: B624 | E100: JetBlue | F100: LAX | G100: JFK | H100: =_xlfn.XLOOKUP(Flights[[#This Row],[Destination]], Airports!$A$2:$A$78, Airports!$D$2:$D$78) -> New York | I100: {=_xlfn.XLOOKUP(Flights[[#This Row],[Destination]],_xlfn._TRO_TRAILING( Airports!A:A),_xlfn._TRO_TRAILING( Airports!E:E), "Not found")} -> NY | J100: 0.27083333 | K100: =HOUR(Flights[[#This Row],[Scheduled Departure]]) -> 6 | L100: 0.26597222 | M100: =(L100-J100)*24*60 -> -7 | N100: =Flights[[#This Row],[Length (min)]]/60 -> 5.1333333 | O100: 308 | P100: 2475 | Q100: =IFERROR(Flights[[#This Row],[Distance]]/Flights[[#This Row],[Length (hr)]], "") -> 482.14286 | R100: 0.61458333 | S100: =IF(Flights[[#This Row],[Length (hr)]]<2, "No meal", IF(Flights[[#This Row],[Length (hr)]]<3.5, "Light meal", "Full meal")) -> Full meal | T100: =IF(AND(Flights[[#This Row],[Airline]]="US Airways", Flights[[#This Row],[Meal]]="Full Meal"), "Yes", "No") -> No | U100: 0.60486111 | V100: -14 | W100: =IF(Flights[[#This Row],[Arrival Delay]] = "", "Cancelled", IF(Flights[[#This Row],[Arrival Delay]]>15, "Delayed", "On time")) -> On time | X100: =IF(Flights[[#This Row],[Status]]<>"Delayed","", IF(Flights[[#This Row],[Arrival Delay]]>120, "Severe", IF(Flights[[#This Row],[Arrival Delay]]>60, "Major", "Moderate"))) | Y100: FALSE | AA100: =IF(OR(AND(Flights[[#This Row],[Status]]="Cancelled", Flights[[#This Row],[Cancellation Reason]]="Airline/Carrier"), Flights[[#This Row],[Delay Type]]="Severe"), "Yes", "No") -> No
A101: 42013 | B101: =WEEKNUM(Flights[[#This Row],[Date]], 1) -> 2 | C101: =WEEKDAY(Flights[[#This Row],[Date]],1) -> 6 | D101: UA330 | E101: United | F101: LAX | G101: IAH | H101: =_xlfn.XLOOKUP(Flights[[#This Row],[Destination]], Airports!$A$2:$A$78, Airports!$D$2:$D$78) -> Houston | I101: {=_xlfn.XLOOKUP(Flights[[#This Row],[Destination]],_xlfn._TRO_TRAILING( Airports!A:A),_xlfn._TRO_TRAILING( Airports!E:E), "Not found")} -> TX | J101: 0.28611111 | K101: =HOUR(Flights[[#This Row],[Scheduled Departure]]) -> 6 | L101: 0.28611111 | M101: =(L101-J101)*24*60 -> 0 | N101: =Flights[[#This Row],[Length (min)]]/60 -> 3.4333333 | O101: 206 | P101: 1379 | Q101: =IFERROR(Flights[[#This Row],[Distance]]/Flights[[#This Row],[Length (hr)]], "") -> 401.65049 | R101: 0.50416667 | S101: =IF(Flights[[#This Row],[Length (hr)]]<2, "No meal", IF(Flights[[#This Row],[Length (hr)]]<3.5, "Light meal", "Full meal")) -> Light meal | T101: =IF(AND(Flights[[#This Row],[Airline]]="US Airways", Flights[[#This Row],[Meal]]="Full Meal"), "Yes", "No") -> No | U101: 0.5125 | V101: 12 | W101: =IF(Flights[[#This Row],[Arrival Delay]] = "", "Cancelled", IF(Flights[[#This Row],[Arrival Delay]]>15, "Delayed", "On time")) -> On time | X101: =IF(Flights[[#This Row],[Status]]<>"Delayed","", IF(Flights[[#This Row],[Arrival Delay]]>120, "Severe", IF(Flights[[#This Row],[Arrival Delay]]>60, "Major", "Moderate"))) | Y101: FALSE | AA101: =IF(OR(AND(Flights[[#This Row],[Status]]="Cancelled", Flights[[#This Row],[Cancellation Reason]]="Airline/Carrier"), Flights[[#This Row],[Delay Type]]="Severe"), "Yes", "No") -> No
A102: 42013 | B102: =WEEKNUM(Flights[[#This Row],[Date]], 1) -> 2 | C102: =WEEKDAY(Flights[[#This Row],[Date]],1) -> 6 | D102: UA1236 | E102: United | F102: LAX | G102: ORD | H102: =_xlfn.XLOOKUP(Flights[[#This Row],[Destination]], Airports!$A$2:$A$78, Airports!$D$2:$D$78) -> Chicago | I102: {=_xlfn.XLOOKUP(Flights[[#This Row],[Destination]],_xlfn._TRO_TRAILING( Airports!A:A),_xlfn._TRO_TRAILING( Airports!E:E), "Not found")} -> IL | J102: 0.29166667 | K102: =HOUR(Flights[[#This Row],[Scheduled Departure]]) -> 7 | L102: 0.29305556 | M102: =(L102-J102)*24*60 -> 2 | N102: =Flights[[#This Row],[Length (min)]]/60 -> 4.65 | O102: 279 | P102: 1744 | Q102: =IFERROR(Flights[[#This Row],[Distance]]/Flights[[#This Row],[Length (hr)]], "") -> 375.05376 | R102: 0.54375 | S102: =IF(Flights[[#This Row],[Length (hr)]]<2, "No meal", IF(Flights[[#This Row],[Length (hr)]]<3.5, "Light meal", "Full meal")) -> Full meal | T102: =IF(AND(Flights[[#This Row],[Airline]]="US Airways", Flights[[#This Row],[Meal]]="Full Meal"), "Yes", "No") -> No | U102: 0.57013889 | V102: 38 | W102: =IF(Flights[[#This Row],[Arrival Delay]] = "", "Cancelled", IF(Flights[[#This Row],[Arrival Delay]]>15, "Delayed", "On time")) -> Delayed | X102: =IF(Flights[[#This Row],[Status]]<>"Delayed","", IF(Flights[[#This Row],[Arrival Delay]]>120, "Severe", IF(Flights[[#This Row],[Arrival Delay]]>60, "Major", "Moderate"))) -> Moderate | Y102: FALSE | AA102: =IF(OR(AND(Flights[[#This Row],[Status]]="Cancelled", Flights[[#This Row],[Cancellation Reason]]="Airline/Carrier"), Flights[[#This Row],[Delay Type]]="Severe"), "Yes", "No") -> No
A103: 42013 | B103: =WEEKNUM(Flights[[#This Row],[Date]], 1) -> 2 | C103: =WEEKDAY(Flights[[#This Row],[Date]],1) -> 6 | D103: US699 | E103: US Airways | F103: LAX | G103: RDU | H103: =_xlfn.XLOOKUP(Flights[[#This Row],[Destination]], Airports!$A$2:$A$78, Airports!$D$2:$D$78) -> Raleigh | I103: {=_xlfn.XLOOKUP(Flights[[#This Row],[Destination]],_xlfn._TRO_TRAILING( Airports!A:A),_xlfn._TRO_TRAILING( Airports!E:E), "Not found")} -> NC | J103: 0.34027778 | K103: =HOUR(Flights[[#This Row],[Scheduled Departure]]) -> 8 | L103: 0.3375 | M103: =(L103-J103)*24*60 -> -4 | N103: =Flights[[#This Row],[Length (min)]]/60 -> 4.75 | O103: 285 | P103: 2239 | Q103: =IFERROR(Flights[[#This Row],[Distance]]/Flights[[#This Row],[Length (hr)]], "") -> 471.36842 | R103: 0.65694444 | S103: =IF(Flights[[#This Row],[Length (hr)]]<2, "No meal", IF(Flights[[#This Row],[Length (hr)]]<3.5, "Light meal", "Full meal")) -> Full meal | T103: =IF(AND(Flights[[#This Row],[Airline]]="US Airways", Flights[[#This Row],[Meal]]="Full Meal"), "Yes", "No") -> Yes | U103: 0.66041667 | V103: 5 | W103: =IF(Flights[[#This Row],[Arrival Delay]] = "", "Cancelled", IF(Flights[[#This Row],[Arrival Delay]]>15, "Delayed", "On time")) -> On time | X103: =IF(Flights[[#This Row],[Status]]<>"Delayed","", IF(Flights[[#This Row],[Arrival Delay]]>120, "Severe", IF(Flights[[#This Row],[Arrival Delay]]>60, "Major", "Moderate"))) | Y103: FALSE | AA103: =IF(OR(AND(Flights[[#This Row],[Status]]="Cancelled", Flights[[#This Row],[Cancellation Reason]]="Airline/Carrier"), Flights[[#This Row],[Delay Type]]="Severe"), "Yes", "No") -> No
A104: 42013 | B104: =WEEKNUM(Flights[[#This Row],[Date]], 1) -> 2 | C104: =WEEKDAY(Flights[[#This Row],[Date]],1) -> 6 | D104: HA1 | E104: Hawaiian | F104: LAX | G104: HNL | H104: =_xlfn.XLOOKUP(Flights[[#This Row],[Destination]], Airports!$A$2:$A$78, Airports!$D$2:$D$78) -> Honolulu | I104: {=_xlfn.XLOOKUP(Flights[[#This Row],[Destination]],_xlfn._TRO_TRAILING( Airports!A:A),_xlfn._TRO_TRAILING( Airports!E:E), "Not found")} -> HI | J104: 0.36111111 | K104: =HOUR(Flights[[#This Row],[Scheduled Departure]]) -> 8 | L104: 0.35833333 | M104: =(L104-J104)*24*60 -> -4 | N104: =Flights[[#This Row],[Length (min)]]/60 -> 5.85 | O104: 351 | P104: 2556 | Q104: =IFERROR(Flights[[#This Row],[Distance]]/Flights[[#This Row],[Length (hr)]], "") -> 436.92308 | R104: 0.51736111 | S104: =IF(Flights[[#This Row],[Length (hr)]]<2, "No meal", IF(Flights[[#This Row],[Length (hr)]]<3.5, "Light meal", "Full meal")) -> Full meal | T104: =IF(AND(Flights[[#This Row],[Airline]]="US Airways", Flights[[#This Row],[Meal]]="Full Meal"), "Yes", "No") -> No | U104: 0.51875 | V104: 2 | W104: =IF(Flights[[#This Row],[Arrival Delay]] = "", "Cancelled", IF(Flights[[#This Row],[Arrival Delay]]>15, "Delayed", "On time")) -> On time | X104: =IF(Flights[[#This Row],[Status]]<>"Delayed","", IF(Flights[[#This Row],[Arrival Delay]]>120, "Severe", IF(Flights[[#This Row],[Arrival Delay]]>60, "Major", "Moderate"))) | Y104: FALSE | AA104: =IF(OR(AND(Flights[[#This Row],[Status]]="Cancelled", Flights[[#This Row],[Cancellation Reason]]="Airline/Carrier"), Flights[[#This Row],[Delay Type]]="Severe"), "Yes", "No") -> No
A105: 42013 | B105: =WEEKNUM(Flights[[#This Row],[Date]], 1) -> 2 | C105: =WEEKDAY(Flights[[#This Row],[Date]],1) -> 6 | D105: AA2 | E105: American Airlines | F105: LAX | G105: JFK | H105: =_xlfn.XLOOKUP(Flights[[#This Row],[Destination]], Airports!$A$2:$A$78, Airports!$D$2:$D$78) -> New York | I105: {=_xlfn.XLOOKUP(Flights[[#This Row],[Destination]],_xlfn._TRO_TRAILING( Airports!A:A),_xlfn._TRO_TRAILING( Airports!E:E), "Not found")} -> NY | J105: 0.375 | K105: =HOUR(Flights[[#This Row],[Scheduled Departure]]) -> 9 | L105: 0.36944444 | M105: =(L105-J105)*24*60 -> -8 | N105: =Flights[[#This Row],[Length (min)]]/60 -> 5.3166667 | O105: 319 | P105: 2475 | Q105: =IFERROR(Flights[[#This Row],[Distance]]/Flights[[#This Row],[Length (hr)]], "") -> 465.51724 | R105: 0.72847222 | S105: =IF(Flights[[#This Row],[Length (hr)]]<2, "No meal", IF(Flights[[#This Row],[Length (hr)]]<3.5, "Light meal", "Full meal")) -> Full meal | T105: =IF(AND(Flights[[#This Row],[Airline]]="US Airways", Flights[[#This Row],[Meal]]="Full Meal"), "Yes", "No") -> No | U105: 0.71597222 | V105: -18 | W105: =IF(Flights[[#This Row],[Arrival Delay]] = "", "Cancelled", IF(Flights[[#This Row],[Arrival Delay]]>15, "Delayed", "On time")) -> On time | X105: =IF(Flights[[#This Row],[Status]]<>"Delayed","", IF(Flights[[#This Row],[Arrival Delay]]>120, "Severe", IF(Flights[[#This Row],[Arrival Delay]]>60, "Major", "Moderate"))) | Y105: FALSE | AA105: =IF(OR(AND(Flights[[#This Row],[Status]]="Cancelled", Flights[[#This Row],[Cancellation Reason]]="Airline/Carrier"), Flights[[#This Row],[Delay Type]]="Severe"), "Yes", "No") -> No
